2024-11-19 09:28:10,148 | WARNING | Goodbye!
2024-11-19 09:28:10,149 | WARNING | Œ¯Ë·Í‡
Traceback (most recent call last):
  File "X:\01._Urban\#_Repeat\04_Repeat_11.11.24\.venv\lib\site-packages\aiohttp\connector.py", line 980, in _wrap_create_connection
    return await self._loop.create_connection(*args, **kwargs)  # type: ignore[return-value]  # noqa
  File "C:\Users\kse.OMC.000\AppData\Local\Programs\Python\Python39\lib\asyncio\base_events.py", line 1090, in create_connection
    transport, protocol = await self._create_connection_transport(
  File "C:\Users\kse.OMC.000\AppData\Local\Programs\Python\Python39\lib\asyncio\base_events.py", line 1120, in _create_connection_transport
    await waiter
  File "C:\Users\kse.OMC.000\AppData\Local\Programs\Python\Python39\lib\asyncio\sslproto.py", line 534, in data_received
    ssldata, appdata = self._sslpipe.feed_ssldata(data)
  File "C:\Users\kse.OMC.000\AppData\Local\Programs\Python\Python39\lib\asyncio\sslproto.py", line 188, in feed_ssldata
    self._sslobj.do_handshake()
  File "C:\Users\kse.OMC.000\AppData\Local\Programs\Python\Python39\lib\ssl.py", line 945, in do_handshake
    self._sslobj.do_handshake()
ssl.SSLCertVerificationError: [SSL: CERTIFICATE_VERIFY_FAILED] certificate verify failed: self signed certificate in certificate chain (_ssl.c:1129)

The above exception was the direct cause of the following exception:

Traceback (most recent call last):
  File "X:\01._Urban\#_Repeat\04_Repeat_11.11.24\.venv\lib\site-packages\aiogram\bot\api.py", line 139, in make_request
    async with session.post(url, data=req, **kwargs) as response:
  File "X:\01._Urban\#_Repeat\04_Repeat_11.11.24\.venv\lib\site-packages\aiohttp\client.py", line 1167, in __aenter__
    self._resp = await self._coro
  File "X:\01._Urban\#_Repeat\04_Repeat_11.11.24\.venv\lib\site-packages\aiohttp\client.py", line 562, in _request
    conn = await self._connector.connect(
  File "X:\01._Urban\#_Repeat\04_Repeat_11.11.24\.venv\lib\site-packages\aiohttp\connector.py", line 540, in connect
    proto = await self._create_connection(req, traces, timeout)
  File "X:\01._Urban\#_Repeat\04_Repeat_11.11.24\.venv\lib\site-packages\aiohttp\connector.py", line 901, in _create_connection
    _, proto = await self._create_direct_connection(req, traces, timeout)
  File "X:\01._Urban\#_Repeat\04_Repeat_11.11.24\.venv\lib\site-packages\aiohttp\connector.py", line 1209, in _create_direct_connection
    raise last_exc
  File "X:\01._Urban\#_Repeat\04_Repeat_11.11.24\.venv\lib\site-packages\aiohttp\connector.py", line 1178, in _create_direct_connection
    transp, proto = await self._wrap_create_connection(
  File "X:\01._Urban\#_Repeat\04_Repeat_11.11.24\.venv\lib\site-packages\aiohttp\connector.py", line 982, in _wrap_create_connection
    raise ClientConnectorCertificateError(req.connection_key, exc) from exc
aiohttp.client_exceptions.ClientConnectorCertificateError: Cannot connect to host api.telegram.org:443 ssl:True [SSLCertVerificationError: (1, '[SSL: CERTIFICATE_VERIFY_FAILED] certificate verify failed: self signed certificate in certificate chain (_ssl.c:1129)')]

During handling of the above exception, another exception occurred:

Traceback (most recent call last):
  File "X:\01._Urban\#_Repeat\04_Repeat_11.11.24\13_Module_#13\module_13_2\module_13_2.py", line 19, in <module>
    executor.start_polling(dp, skip_updates=True)
  File "X:\01._Urban\#_Repeat\04_Repeat_11.11.24\.venv\lib\site-packages\aiogram\utils\executor.py", line 45, in start_polling
    executor.start_polling(
  File "X:\01._Urban\#_Repeat\04_Repeat_11.11.24\.venv\lib\site-packages\aiogram\utils\executor.py", line 320, in start_polling
    loop.run_until_complete(self._startup_polling())
  File "C:\Users\kse.OMC.000\AppData\Local\Programs\Python\Python39\lib\asyncio\base_events.py", line 647, in run_until_complete
    return future.result()
  File "X:\01._Urban\#_Repeat\04_Repeat_11.11.24\.venv\lib\site-packages\aiogram\utils\executor.py", line 372, in _startup_polling
    await self._welcome()
  File "X:\01._Urban\#_Repeat\04_Repeat_11.11.24\.venv\lib\site-packages\aiogram\utils\executor.py", line 361, in _welcome
    user = await self.dispatcher.bot.me
  File "X:\01._Urban\#_Repeat\04_Repeat_11.11.24\.venv\lib\site-packages\aiogram\bot\bot.py", line 30, in me
    setattr(self, '_me', await self.get_me())
  File "X:\01._Urban\#_Repeat\04_Repeat_11.11.24\.venv\lib\site-packages\aiogram\bot\bot.py", line 233, in get_me
    result = await self.request(api.Methods.GET_ME, payload)
  File "X:\01._Urban\#_Repeat\04_Repeat_11.11.24\.venv\lib\site-packages\aiogram\bot\base.py", line 236, in request
    return await api.make_request(await self.get_session(), self.server, self.__token, method, data, files,
  File "X:\01._Urban\#_Repeat\04_Repeat_11.11.24\.venv\lib\site-packages\aiogram\bot\api.py", line 142, in make_request
    raise exceptions.NetworkError(f"aiohttp client throws an error: {e.__class__.__name__}: {e}")
aiogram.utils.exceptions.NetworkError: Aiohttp client throws an error: ClientConnectorCertificateError: Cannot connect to host api.telegram.org:443 ssl:True [SSLCertVerificationError: (1, '[SSL: CERTIFICATE_VERIFY_FAILED] certificate verify failed: self signed certificate in certificate chain (_ssl.c:1129)')]
